Workbook

Sheet How to use
A1: EAGLES ALL-22 CHART
A4: WHICH CELLS YOU TOUCH
A5: Yellow cells on the Chart tab | B5: You fill these in. Every one is a dropdown except Dist, Yds, Target, PlayForge Link and Notes.
A6: Column A, Play ID | B6: Fills itself. Type the week in column B and the ID appears as W1-001, W1-002 and so on.
A7: Lists tab | B7: The dropdown vocabulary. Add your own terms at the bottom of a column and they show up in the dropdown.
A8: Summary tab | B8: All formulas. Nothing to fill in.
A10: THE ROUTINE
A11: 1. Live watch | B11: Atlas voice notes. Fragments only: the ID, then three or four words. "W1-014, condensed, run right, big cutback."
A12: 2. All-22 pass | B12: One row per snap. Sideline at normal speed for the data columns, endzone frame by frame for Run Family and Run Tag. The endzone angle is the only one that shows OL steps.
A13: 3. Draw | B13: Only the rows where New Concept = Yes. Most snaps repeat a concept with a different formation or tag. Draw the concept once, then add formation variants.
A15: THE HABITS THAT MAKE IT WORK
A16: One ID everywhere | B16: The Play ID goes in the Atlas note, this chart, and the PlayForge play name. Same string in all three.
A17: Chart the run game first | B17: Play action hangs off the run game. Set Keeper Fake = Yes whenever the QB finishes the fake, and you will see the run and play-pass pairs appear.
A18: Flag, don't stall | B18: If you cannot name it, set Pass Concept = UNKNOWN - review or Run Tag = Unknown, write what the tackle and the TE did in Notes, and move on. Those rows are the ones to bring back for help.
A19: Function over verbiage | B19: Eagles verbiage is not recoverable from film. Name what you see using this vocabulary and stay consistent. Consistency beats correctness here.
A21: READING THE OL, FAST
A22: Playside tackle's first step | B22: Reaching for width = 18-19 outside zone. Vertical into the B gap = 15-14 inside zone. Down block with a guard pulling = 12-13 gap.
A23: Blockers outside the tackle | B23: Two = Zorro / Zap family. One pulling flat = Taxi / Truck / Cab. None = base zone.
A24: Watch the F, not the ball | B24: The F tells you the formation family and the strength before the snap.

Sheet Lists
A1: DROPDOWN SOURCE VALUES
A2: Pulled from the 2019 Green Bay (LaFleur) playbook. Add your own terms to the bottom of any column and the dropdown picks them up automatically.
A4: Personnel | B4: FormFamily | C4: Formation | D4: Strength | E4: Adjust | F4: Motion | G4: Backfield | H4: PlayType | I4: RunFamily | J4: RunTag | K4: Protection | L4: Concept | M4: Screen | N4: Front | O4: Coverage | P4: Pressure | Q4: Hash | R4: FieldZone | S4: Down | T4: Result | U4: YesNo | V4: Drawn
A5: 21 | B5: 2 Back | C5: I | D5: Rt | E5: (none) | F5: (none) | G5: Under Center | H5: Run | I5: Outside Zone 18-19 | J5: (none) | K5: 2 Jet | L5: Stick | M5: n/a | N5: Base 4-3 | O5: Cover 0 | P5: None | Q5: Left | R5: Own 1-10 | S5: 1 | T5: Run - Gain | U5: Yes | V5: No
A6: 12 | B6: 3x1 'T' | C6: Strong | D6: Lt | E6: Close | F6: F Rt | G6: Gun | H6: Pass - Quick | I6: Outside Zone 38-39 (gun) | J6: Zorro | K6: 3 Jet | L6: Stick Bow | M6: HB Slow | N6: Over | O6: Cover 1 | P6: Single LB | Q6: Right | R6: Own 11-20 | S6: 2 | T6: Run - Loss | U6: No | V6: Yes
A7: 11 | B7: Bunch 'B' | C7: Weak | E7: Closer | F7: F Lt | G7: Pistol | H7: Pass - Drop Back | I7: Inside Zone 15-14 | J7: Zap | K7: 200 Jet | L7: Omaha | M7: Chip | N7: Under | O7: Cover 11 | P7: LB Blitz | Q7: Middle | R7: Own 21-40 | S7: 3 | T7: Complete | V7: Not needed - repeat
A8: 20 | B8: 2x2 'D' | C8: Red | E8: Clamp | F8: H Rt | G8: Empty | H8: Pass - Empty | I8: Inside Zone 35-34 (gun) | J8: Arc | K8: 300 Jet | L8: Stitch | M8: Alley | N8: 50 / Odd | O8: Cover 2 | P8: DB Blitz | R8: Own 41 to Mid | S8: 4 | T8: Incomplete
A9: 10 | B9: 2x2 Stack 'S' | C9: Change | E9: Click | F9: H Lt | H9: Play Pass | I9: Gap 12-13 | J9: Force | K9: 2 Scat | L9: Dragon Over | M9: Path | N9: 30 | O9: Cover 22 | P9: Double A | R9: Mid to Opp 41 | T9: Throwaway
A10: 02 | B10: 1x3 'F' | C10: West | E10: Open | F10: Bump | H10: Movement | I10: Gap 32-33 (gun) | J10: Support | K10: 3 Scat | L10: Dragon Wheel | M10: Slammer | N10: Bear | O10: 2-Man | P10: Nickel Blitz | R10: Opp 40-21 | T10: Sack
A11: 01 | B11: 1x3 Bunch 'CR' | C11: East | E11: Out | F11: Hay | H11: Screen | I11: Toss | J11: Quatro | K11: Scram | L11: Coin Cut | M11: Jailbreak | N11: Even | O11: Cover 3 | P11: Sim / Creeper | R11: Opp 20-11 (Red) | T11: Interception
A12: 22 | B12: Special | C12: Trips | E12: Off | F12: Hax | H12: QB Run | I12: Draw | J12: Wanda | K12: 20 | L12: Coin Target | M12: Prison | N12: Nickel | O12: Cover 33 | P12: Unknown | R12: Opp 10-1 (Goal Line) | T12: Fumble
A13: 22X | B13: Big | C13: Trio | E13: Tight | F13: Foy | H13: Scramble | I13: Goal Line | J13: Weasel | K13: 21 | L13: Coin Buffalo | M13: Alcatraz | N13: Dime | O13: Cover 4 / Quarters | T13: Touchdown
A14: 22Z | B14: Empty | C14: Train | E14: Tighter | F14: Fox | H14: Penalty / No Play | I14: QB Designed | J14: Washy | K14: H2 | L14: Choice Swab | M14: Flow | N14: Goal Line | O14: Cover 6 | T14: Penalty
A15: 13 | B15: Goal Line | C15: Trout | E15: Slot | F15: Home | I15: n/a | J15: Wizz | K15: H3 | L15: Flag Bow | M15: Streamer | N15: Unknown | O15: Match - Palms | T15: Scramble
A16: 13X | B16: Unknown | C16: Trax | E16: Zoom | F16: Mo | I16: Unknown | J16: Taxi | K16: H200 | L16: Flag Swab | M16: Swinger | O16: Match - other
A17: 13Z | C17: Bunch | E17: Hip | F17: Short | J17: Truck | K17: H300 | L17: Go Shade | M17: Sifter | O17: Unknown
A18: 23 | C18: Bin | E18: Hop | F18: Shorty | J18: Cab | K18: 64 | L18: Shade Pump | M18: William
C19: Buddy | E19: Snug | F19: Counter | J19: Sideline | K19: 65 | L19: Go Shadow | M19: Willie
C20: Box | E20: Ace | F20: Fly | J20: Uber | K20: 364 | L20: Florida | M20: Y Screen
C21: Deuce | E21: Book | F21: Behind | J21: Structure | K21: 365 | L21: Co | M21: Special Screen
C22: Dice | E22: Numbers | F22: Righty | J22: Str | K22: 24 | L22: Curl Burst | M22: Special Chip Screen
C23: Dixie | E23: Edge | F23: Lefty | J23: Weak | K23: 25 | L23: Trunk Target
C24: Dyno | E24: (+) | F24: Z Rt | J24: Split | K24: Y6 | L24: Arches
C25: Stack | E25: (-) | F25: Z Lt | J25: Man | K25: Y7 | L25: Corner
C26: South | E26: Extend | F26: Z Short | J26: Wash | K26: Flow 6 | L26: Arches Clack
C27: Stamp | E27: Multiple | F27: Z Counter | J27: Wendy | K27: Flow 7 | L27: Artichoke
C28: Swamp | F28: Z Mo | J28: Mike | K28: Play Pass (named for run) | L28: Storm
C29: Sink | F29: Lab | J29: Duo | K29: Screen | L29: Shot Buffalo
C30: Snug | F30: Rat | J30: Dos | K30: n/a | L30: Lookie Ninja
C31: Fast | F31: Trixie | J31: Power | K31: Unknown | L31: Lookie Bamboo
C32: Fit | F32: Oscar | J32: Power Load | L32: Skinner Return
C33: Foot | F33: Reload | J33: Pop | L33: Scar Return Pile
C34: Crip | F34: Shift - other | J34: Counter | L34: H Coco Mini
C35: Crack | J35: Stutter | L35: Mink Trash
C36: Crush | J36: Stanley | L36: Cash Stucko
C37: Cruz | J37: Sift | L37: Pull Shallow
C38: Gold | J38: Wipe | L38: Fun Swab
C39: Bone | J39: Jam | L39: Tree
C40: Wax | J40: Under | L40: Tree Swab
C41: Tank | J41: Bear | L41: Tree Trash
...

Sheet Chart
A1: ALL-22 CHART
A2: One row per snap. Fill the yellow columns; Play ID fills itself. Chart every play, then draw only the ones marked New Concept = Yes.
A4: Play ID | B4: Wk | C4: Qtr | D4: Down | E4: Dist | F4: Field Zone | G4: Hash | H4: Personnel | I4: Form Family | J4: Formation | K4: Str | L4: Adjust Tag | M4: Motion / Shift | N4: Backfield | O4: Play Type | P4: Run Family | Q4: Run Tag | R4: Protection | S4: Pass Concept | T4: Screen Type | U4: Keeper Fake? | V4: Target | W4: Result | X4: Yds | Y4: Front | Z4: Coverage | AA4: Pressure | AB4: New Concept? | AC4: Drawn in PF? | AD4: PlayForge Link | AE4: Notes
A5: =IF(B5="","","W"&B5&"-"&TEXT(COUNTIF($B$5:B5,B5),"000")) -> W1-001 | B5: 1 | C5: 1 | D5: 1 | E5: 10 | F5: Own 21-40 | G5: Left | H5: 12 | I5: 3x1 'T' | K5: Rt | N5: Under Center | V5: S.Barkley | W5: Incomplete | X5: 0 | AE5: PHI 35. J.Hurts pass incomplete short right to S.Barkley. | Set: Wicks wide R, Smith slot R, Goedert inline R, Mundt inline L. Motion: Smith / slot R / across to L / at snap (2x2 as snapped).
A6: =IF(B6="","","W"&B6&"-"&TEXT(COUNTIF($B$5:B6,B6),"000")) -> W1-002 | B6: 1 | C6: 1 | D6: 2 | E6: 10 | F6: Own 21-40 | G6: Left | H6: 12 | I6: 3x1 'T' | K6: Rt | N6: Under Center | O6: Run | V6: S.Barkley | W6: Run - Gain | X6: 5 | AE6: PHI 35. S.Barkley right guard to PHI 40 for 5 yards. | Set: Mundt inline R, Wicks flexed R, Goedert split wide R, Smith wide L. Motion: Goedert / wide R / in toward formation / at snap.
A7: =IF(B7="","","W"&B7&"-"&TEXT(COUNTIF($B$5:B7,B7),"000")) -> W1-003 | B7: 1 | C7: 1 | D7: 3 | E7: 5 | F7: Own 21-40 | G7: Right | H7: 11 | I7: 2x2 'D' | K7: Rt | N7: Gun | O7: Scramble | V7: J.Hurts | W7: Scramble | X7: 6 | AE7: PHI 40. (Shotgun) J.Hurts scrambles left tackle, ran ob at PHI 46 for 6 yards. | Set: 1 WR wide R + Goedert off-ball wing R, 2 WR L. No motion. Hash from Sideline only (Endzone clip missing).
A8: =IF(B8="","","W"&B8&"-"&TEXT(COUNTIF($B$5:B8,B8),"000")) -> W1-004 | B8: 1 | C8: 1 | D8: 1 | E8: 10 | F8: Own 41 to Mid | G8: Left | H8: 12 | I8: 3x1 'T' | K8: Rt | N8: Under Center | O8: Run | V8: S.Barkley | W8: Run - Loss | X8: -1 | AE8: PHI 46. S.Barkley left end to PHI 45 for -1 yards. | Set: Goedert inline R, Cooper just outside, Smith tight outside Cooper, Mundt inline L. Motion: Smith / tight R / behind LOS to tight L / at snap (2x2 tight as snapped).
A9: =IF(B9="","","W"&B9&"-"&TEXT(COUNTIF($B$5:B9,B9),"000")) -> W1-005 | B9: 1 | C9: 1 | D9: 2 | E9: 11 | F9: Own 41 to Mid | G9: Left | H9: 11 | I9: 2x2 'D' | K9: Rt | N9: Gun | V9: M.Lemon | W9: Complete | X9: 3 | AE9: PHI 45. (Shotgun) J.Hurts pass short left to M.Lemon, pushed ob at PHI 48 for 3 yards. | No motion.
A10: =IF(B10="","","W"&B10&"-"&TEXT(COUNTIF($B$5:B10,B10),"000")) -> W1-006 | B10: 1 | C10: 1 | D10: 3 | E10: 8 | F10: Own 41 to Mid | G10: Left | H10: 11 | I10: 2x2 'D' | K10: Rt | N10: Gun | V10: D.Wicks | W10: Incomplete | X10: 0 | AE10: PHI 48. (Shotgun) J.Hurts pass incomplete short left to D.Wicks. | Shift: slot R / behind QB to slot L / stop-and-set (3x1 Rt before shift).
A11: =IF(B11="","","W"&B11&"-"&TEXT(COUNTIF($B$5:B11,B11),"000")) -> W1-007 | B11: 1 | C11: 1 | D11: 1 | E11: 10 | F11: Own 21-40 | G11: Left | H11: 12 | I11: 3x1 'T' | K11: Rt | N11: Under Center | O11: Run | V11: S.Barkley | W11: Penalty | AE11: PHI 39. S.Barkley left end for 5, wiped by holding on C.Jurgens (10 yds, enforced at PHI 40). Down replayed. | Set: Mundt inline R, Goedert wing R, Wicks wide R, Smith wide L. Motion: Goedert / wing R / across backfield to L / at snap (2-back look as snapped).
A12: =IF(B12="","","W"&B12&"-"&TEXT(COUNTIF($B$5:B12,B12),"000")) -> W1-008 | B12: 1 | C12: 1 | D12: 1 | E12: 19 | F12: Own 21-40 | G12: Left | H12: 11 | I12: 2x2 'D' | N12: Gun | V12: M.Lemon | W12: Complete | X12: -5 | AE12: PHI 30. (Shotgun) J.Hurts pass short right to M.Lemon to PHI 25 for -5 yards. | Str unknown: Goedert not found. Motion: Lemon / L slot / across backfield to R / at snap.
A13: =IF(B13="","","W"&B13&"-"&TEXT(COUNTIF($B$5:B13,B13),"000")) -> W1-009 | B13: 1 | C13: 1 | D13: 2 | E13: 24 | F13: Own 21-40 | G13: Right | H13: 11 | I13: 3x1 'T' | K13: Rt | N13: Gun | V13: D.Smith | W13: Complete | X13: 12 | AE13: PHI 25. (Shotgun) J.Hurts pass short middle to D.Smith to PHI 37 for 12 yards. | Set: Goedert inline R, Wicks slot R, Lemon outside Wicks, Smith wide L. Motion: Lemon / outside R / across to slot L / at snap (2x2 as snapped).
A14: =IF(B14="","","W"&B14&"-"&TEXT(COUNTIF($B$5:B14,B14),"000")) -> W1-010 | B14: 1 | C14: 1 | D14: 3 | E14: 12 | F14: Own 21-40 | G14: Right | H14: 11 | I14: 2x2 'D' | K14: Rt | N14: Gun | W14: Sack | X14: -9 | AE14: PHI 37. (Shotgun) J.Hurts sacked at PHI 28 for -9 yards (F.Luvu). | Set (after shift): WR wide R + Goedert wing R, 2 WR L. Shift: Goedert / left side / across to wing R / stop-and-set (3x1 Lt before shift).
A15: =IF(B15="","","W"&B15&"-"&TEXT(COUNTIF($B$5:B15,B15),"000")) -> W1-011 | B15: 1 | C15: 1 | D15: 1 | E15: 10 | F15: Own 21-40 | G15: Left | H15: 12 | I15: 2x2 'D' | K15: Lt | N15: Under Center | O15: Run | V15: S.Barkley | W15: Run - Gain | X15: 6 | AE15: PHI 24. S.Barkley right end to PHI 30 for 6 yards. | Str by Y tiebreak (Goedert side). Motion: Smith / wide L / across toward R / at snap.
A16: =IF(B16="","","W"&B16&"-"&TEXT(COUNTIF($B$5:B16,B16),"000")) -> W1-012 | B16: 1 | C16: 1 | D16: 2 | E16: 4 | F16: Own 21-40 | G16: Right | H16: 13 | I16: Big | K16: Lt | N16: Under Center | V16: D.Wicks | W16: Complete | X16: 64 | AE16: PHI 30. J.Hurts pass deep right to D.Wicks to WAS 6 for 64 yards. No shotgun tag: play-action candidate. | Double tight L, Wicks only wideout.
A17: =IF(B17="","","W"&B17&"-"&TEXT(COUNTIF($B$5:B17,B17),"000")) -> W1-013 | B17: 1 | C17: 1 | D17: 1 | E17: 6 | F17: Opp 10-1 (Goal Line) | G17: Right | H17: 12 | I17: 2x2 'D' | K17: Rt | N17: Under Center | O17: Run | V17: S.Barkley | W17: Penalty | AE17: WAS 6. S.Barkley left tackle for 4, no play: holding on C.Jurgens. | Str by Y tiebreak (Goedert side). Motion: Wicks / wide L / in tight to LT / at snap.
A18: =IF(B18="","","W"&B18&"-"&TEXT(COUNTIF($B$5:B18,B18),"000")) -> W1-014 | B18: 1 | C18: 1 | D18: 1 | E18: 16 | F18: Opp 20-11 (Red) | G18: Left | H18: 11 | I18: 3x1 'T' | K18: Rt | N18: Gun | O18: Run | V18: S.Barkley | W18: Run - Loss | X18: -2 | AE18: WAS 16. (Shotgun) S.Barkley up the middle to WAS 18 for -2 yards. | No motion. Hash: Left on both angles at full zoom; conflicts with W1-013 Right after a no-play. Video kept.
A19: =IF(B19="","","W"&B19&"-"&TEXT(COUNTIF($B$5:B19,B19),"000")) -> W1-015 | B19: 1 | C19: 2 | D19: 2 | E19: 18 | F19: Opp 20-11 (Red) | G19: Left | H19: 11 | I19: 3x1 'T' | K19: Rt | N19: Gun | O19: Run | V19: S.Barkley | W19: Run - Gain | X19: 1 | AE19: WAS 18. (Shotgun) S.Barkley right tackle to WAS 17 for 1 yard. | No motion.
A20: =IF(B20="","","W"&B20&"-"&TEXT(COUNTIF($B$5:B20,B20),"000")) -> W1-016 | B20: 1 | C20: 2 | D20: 3 | E20: 17 | F20: Opp 20-11 (Red) | G20: Right | H20: 11 | I20: 2x2 'D' | K20: Rt | N20: Gun | V20: D.Goedert | W20: Touchdown | X20: 17 | AE20: WAS 17. (Shotgun) J.Hurts pass deep right to D.Goedert for 17 yards, TD. | Goedert flexed R (traced on release, Medium).
A21: =IF(B21="","","W"&B21&"-"&TEXT(COUNTIF($B$5:B21,B21),"000")) -> W1-017 | B21: 1 | C21: 2 | D21: 1 | E21: 10 | F21: Own 21-40 | G21: Right | H21: 11 | I21: 2 Back | K21: Rt | N21: Under Center | O21: Run | V21: S.Barkley | W21: Run - Gain | X21: 4 | AE21: PHI 27. S.Barkley left tackle to PHI 31 for 4 yards. | Str by Y tiebreak (Goedert side). Motion: receiver / behind QB / out to wing R / at snap.
A22: =IF(B22="","","W"&B22&"-"&TEXT(COUNTIF($B$5:B22,B22),"000")) -> W1-018 | B22: 1 | C22: 2 | D22: 2 | E22: 6 | F22: Own 21-40 | G22: Left | H22: 11 | I22: 2x2 'D' | K22: Rt | N22: Gun | V22: M.Lemon | W22: Incomplete | X22: 0 | AE22: PHI 31. (Shotgun) J.Hurts pass incomplete short left to M.Lemon (K.Chaisson). | Goedert #88 flexed R on Endzone.
A23: =IF(B23="","","W"&B23&"-"&TEXT(COUNTIF($B$5:B23,B23),"000")) -> W1-019 | B23: 1 | C23: 2 | D23: 3 | E23: 6 | F23: Own 21-40 | G23: Left | H23: 11 | I23: 3x1 'T' | K23: Rt | N23: Gun | V23: D.Wicks | W23: Incomplete | X23: 0 | AE23: PHI 31. (Shotgun) J.Hurts pass incomplete deep right to D.Wicks. | No motion.
A24: =IF(B24="","","W"&B24&"-"&TEXT(COUNTIF($B$5:B24,B24),"000")) -> W1-020 | B24: 1 | C24: 2 | D24: 1 | E24: 10 | F24: Own 21-40 | G24: Right | H24: 11 | I24: 2x2 'D' | K24: Rt | N24: Under Center | W24: Incomplete | X24: 0 | AE24: PHI 38. J.Hurts pass incomplete short right, no target listed. | Motion: WR / wide R / in toward formation / at snap.
A25: =IF(B25="","","W"&B25&"-"&TEXT(COUNTIF($B$5:B25,B25),"000")) -> W1-021 | B25: 1 | C25: 2 | D25: 2 | E25: 10 | F25: Own 21-40 | G25: Right | H25: 11 | I25: 3x1 'T' | K25: Lt | N25: Gun | O25: Run | V25: S.Barkley | W25: Run - Gain | X25: 8 | AE25: PHI 38. (Shotgun) S.Barkley left end to PHI 46 for 8 yards. | Sideline only (Endzone clip missing).
A26: =IF(B26="","","W"&B26&"-"&TEXT(COUNTIF($B$5:B26,B26),"000")) -> W1-022 | B26: 1 | C26: 2 | D26: 3 | E26: 2 | F26: Own 41 to Mid | G26: Left | H26: 11 | I26: 3x1 'T' | K26: Rt | N26: Gun | O26: Run | V26: S.Barkley | W26: Run - Gain | X26: 42 | AE26: PHI 46. (No Huddle, Shotgun) S.Barkley right guard to WAS 12 for 42 yards. | Sideline only (Endzone clip missing).
A27: =IF(B27="","","W"&B27&"-"&TEXT(COUNTIF($B$5:B27,B27),"000")) -> W1-023 | B27: 1 | C27: 2 | D27: 1 | E27: 10 | F27: Opp 20-11 (Red) | G27: Right | H27: 12 | I27: 3x1 'T' | K27: Lt | N27: Under Center | O27: Run | V27: T.Bigsby | W27: Run - Gain | X27: 3 | AE27: WAS 12. T.Bigsby up the middle to WAS 9 for 3 yards. | Double tight L plus a WR.
A28: =IF(B28="","","W"&B28&"-"&TEXT(COUNTIF($B$5:B28,B28),"000")) -> W1-024 | B28: 1 | C28: 2 | D28: 2 | E28: 7 | F28: Opp 10-1 (Goal Line) | G28: Middle | H28: 12 | I28: 2x2 'D' | K28: Rt | N28: Gun | V28: D.Wicks | W28: Touchdown | X28: 9 | AE28: WAS 9. (Shotgun) J.Hurts pass short left to D.Wicks for 9 yards, TD. | No motion.
A29: =IF(B29="","","W"&B29&"-"&TEXT(COUNTIF($B$5:B29,B29),"000")) -> W1-025 | B29: 1 | C29: 2 | D29: 1 | E29: 10 | F29: Own 21-40 | G29: Left | H29: 11 | I29: 3x1 'T' | K29: Lt | N29: Gun | O29: Scramble | V29: J.Hurts | W29: Scramble | X29: 5 | AE29: PHI 29. (Shotgun) J.Hurts scrambles right end to PHI 34 for 5 yards. 2-min drill. | Motion: WR / wide L / across to R / at snap.
A30: =IF(B30="","","W"&B30&"-"&TEXT(COUNTIF($B$5:B30,B30),"000")) -> W1-026 | B30: 1 | C30: 2 | D30: 2 | E30: 5 | F30: Own 21-40 | G30: Right | H30: 11 | I30: 2x2 'D' | K30: Rt | N30: Gun | V30: D.Goedert | W30: Complete | X30: 5 | AE30: PHI 34. (No Huddle, Shotgun) J.Hurts pass short right to D.Goedert to PHI 39 for 5 yards. | No motion.
A31: =IF(B31="","","W"&B31&"-"&TEXT(COUNTIF($B$5:B31,B31),"000")) -> W1-027 | B31: 1 | C31: 2 | D31: 1 | E31: 10 | F31: Own 21-40 | G31: Right | H31: 11 | I31: 2x2 'D' | K31: Rt | N31: Gun | V31: W.Shipley | W31: Complete | X31: 8 | AE31: PHI 39. (No Huddle, Shotgun) J.Hurts pass short right to W.Shipley, ran ob at PHI 47 for 8 yards. | No motion.
A32: =IF(B32="","","W"&B32&"-"&TEXT(COUNTIF($B$5:B32,B32),"000")) -> W1-028 | B32: 1 | C32: 2 | D32: 2 | E32: 2 | F32: Own 41 to Mid | G32: Right | H32: 11 | I32: 3x1 'T' | K32: Rt | N32: Gun | V32: D.Smith | W32: Incomplete | X32: 0 | AE32: PHI 47. (Shotgun) J.Hurts pass incomplete deep left to D.Smith. | Mundt is the TE. Motion: R slot / in toward box / at snap.
A33: =IF(B33="","","W"&B33&"-"&TEXT(COUNTIF($B$5:B33,B33),"000")) -> W1-029 | B33: 1 | C33: 2 | D33: 3 | E33: 2 | F33: Own 41 to Mid | G33: Right | H33: 11 | I33: 3x1 'T' | K33: Lt | N33: Gun | V33: D.Smith | W33: Incomplete | X33: 0 | AE33: PHI 47. (Shotgun) J.Hurts pass incomplete short middle to D.Smith (C.Omenihu). | Mundt is the TE. Motion: WR / wide L / across to R next to Mundt / at snap.
A34: =IF(B34="","","W"&B34&"-"&TEXT(COUNTIF($B$5:B34,B34),"000")) -> W1-030 | B34: 1 | C34: 3 | D34: 1 | E34: 10 | F34: Own 21-40 | G34: Right | H34: 12 | I34: 2x2 'D' | K34: Lt | N34: Under Center | O34: Run | V34: S.Barkley | W34: Run - Loss | X34: -1 | AE34: PHI 26. S.Barkley right guard to PHI 25 for -1 yards. | Str by Y tiebreak (Goedert side). Hash confirmed Right on full-zoom recheck.
A35: =IF(B35="","","W"&B35&"-"&TEXT(COUNTIF($B$5:B35,B35),"000")) -> W1-031 | B35: 1 | C35: 3 | D35: 2 | E35: 11 | F35: Own 21-40 | G35: Right | H35: 11 | I35: 2x2 'D' | N35: Gun | V35: M.Lemon | W35: Complete | X35: -3 | AE35: PHI 25. (Shotgun) J.Hurts pass short left to M.Lemon to PHI 22 for -3 yards. | Str unknown: Y not readable.
A36: =IF(B36="","","W"&B36&"-"&TEXT(COUNTIF($B$5:B36,B36),"000")) -> W1-032 | B36: 1 | C36: 3 | D36: 3 | E36: 14 | F36: Own 21-40 | G36: Left | H36: 11 | I36: 2x2 'D' | K36: Rt | N36: Gun | V36: D.Goedert | W36: Complete | X36: 12 | AE36: PHI 22. (Shotgun) J.Hurts pass short left to D.Goedert, pushed ob at PHI 34 for 12 yards. | Sideline only.
A37: =IF(B37="","","W"&B37&"-"&TEXT(COUNTIF($B$5:B37,B37),"000")) -> W1-033 | B37: 1 | C37: 3 | D37: 1 | E37: 10 | F37: Own 11-20 | H37: 12 | I37: 3x1 'T' | K37: Rt | N37: Under Center | W37: Sack | X37: -6 | AE37: PHI 20. J.Hurts sacked at PHI 14 for -6 yards (S.Styles). No shotgun tag: play-action candidate. | Hash unknown (drive start, single angle). Sideline only.
A38: =IF(B38="","","W"&B38&"-"&TEXT(COUNTIF($B$5:B38,B38),"000")) -> W1-034 | B38: 1 | C38: 3 | D38: 2 | E38: 16 | F38: Own 11-20 | G38: Left | H38: 11 | I38: 3x1 'T' | K38: Rt | N38: Gun | V38: D.Smith | W38: Complete | X38: 10 | AE38: PHI 14. (Shotgun) J.Hurts pass short left to D.Smith to PHI 24 for 10 yards. | Sideline only.
A39: =IF(B39="","","W"&B39&"-"&TEXT(COUNTIF($B$5:B39,B39),"000")) -> W1-035 | B39: 1 | C39: 3 | D39: 3 | E39: 6 | F39: Own 21-40 | G39: Left | H39: 11 | I39: 2x2 'D' | K39: Lt | N39: Gun | V39: D.Smith | W39: Incomplete | X39: 0 | AE39: PHI 24. (Shotgun) J.Hurts pass incomplete short left to D.Smith. | Sideline only.
A40: =IF(B40="","","W"&B40&"-"&TEXT(COUNTIF($B$5:B40,B40),"000")) -> W1-036 | B40: 1 | C40: 3 | D40: 1 | E40: 10 | F40: Own 41 to Mid | H40: 12 | I40: 2x2 'D' | N40: Under Center | O40: Run | V40: S.Barkley | W40: Run - Gain | X40: 3 | AE40: PHI 44. S.Barkley right tackle to PHI 47 for 3 yards. | Hash and Str unknown: neither TE number readable, single angle.
A41: =IF(B41="","","W"&B41&"-"&TEXT(COUNTIF($B$5:B41,B41),"000")) -> W1-037 | B41: 1 | C41: 3 | D41: 2 | E41: 7 | F41: Own 41 to Mid | G41: Right | H41: 12 | I41: 3x1 'T' | K41: Lt | N41: Under Center | O41: Run | V41: S.Barkley | W41: Run - Loss | X41: -3 | AE41: PHI 47. S.Barkley right guard to PHI 44 for -3 yards (S.Styles).
...

Sheet Summary
A1: WHAT THE CHART IS TELLING YOU
A2: Total plays charted | B2: =COUNT(Chart!$B$5:$B$1004) -> 1
A4: PLAY TYPE | B4: Plays | C4: % of charted | D4: Avg yds
A5: Run | B5: =COUNTIF(Chart!$O$5:$O$1004,A5) -> 1 | C5: =IFERROR(B5/$B$2,0) -> 1 | D5: =IFERROR(AVERAGEIF(Chart!$O$5:$O$1004,A5,Chart!$X$5:$X$1004),0) -> 6
A6: Pass - Quick | B6: =COUNTIF(Chart!$O$5:$O$1004,A6) -> 0 | C6: =IFERROR(B6/$B$2,0) -> 0 | D6: =IFERROR(AVERAGEIF(Chart!$O$5:$O$1004,A6,Chart!$X$5:$X$1004),0) -> 0
A7: Pass - Drop Back | B7: =COUNTIF(Chart!$O$5:$O$1004,A7) -> 0 | C7: =IFERROR(B7/$B$2,0) -> 0 | D7: =IFERROR(AVERAGEIF(Chart!$O$5:$O$1004,A7,Chart!$X$5:$X$1004),0) -> 0
A8: Pass - Empty | B8: =COUNTIF(Chart!$O$5:$O$1004,A8) -> 0 | C8: =IFERROR(B8/$B$2,0) -> 0 | D8: =IFERROR(AVERAGEIF(Chart!$O$5:$O$1004,A8,Chart!$X$5:$X$1004),0) -> 0
A9: Play Pass | B9: =COUNTIF(Chart!$O$5:$O$1004,A9) -> 0 | C9: =IFERROR(B9/$B$2,0) -> 0 | D9: =IFERROR(AVERAGEIF(Chart!$O$5:$O$1004,A9,Chart!$X$5:$X$1004),0) -> 0
A10: Movement | B10: =COUNTIF(Chart!$O$5:$O$1004,A10) -> 0 | C10: =IFERROR(B10/$B$2,0) -> 0 | D10: =IFERROR(AVERAGEIF(Chart!$O$5:$O$1004,A10,Chart!$X$5:$X$1004),0) -> 0
A11: Screen | B11: =COUNTIF(Chart!$O$5:$O$1004,A11) -> 0 | C11: =IFERROR(B11/$B$2,0) -> 0 | D11: =IFERROR(AVERAGEIF(Chart!$O$5:$O$1004,A11,Chart!$X$5:$X$1004),0) -> 0
A12: QB Run | B12: =COUNTIF(Chart!$O$5:$O$1004,A12) -> 0 | C12: =IFERROR(B12/$B$2,0) -> 0 | D12: =IFERROR(AVERAGEIF(Chart!$O$5:$O$1004,A12,Chart!$X$5:$X$1004),0) -> 0
A13: Scramble | B13: =COUNTIF(Chart!$O$5:$O$1004,A13) -> 0 | C13: =IFERROR(B13/$B$2,0) -> 0 | D13: =IFERROR(AVERAGEIF(Chart!$O$5:$O$1004,A13,Chart!$X$5:$X$1004),0) -> 0
A14: Penalty / No Play | B14: =COUNTIF(Chart!$O$5:$O$1004,A14) -> 0 | C14: =IFERROR(B14/$B$2,0) -> 0 | D14: =IFERROR(AVERAGEIF(Chart!$O$5:$O$1004,A14,Chart!$X$5:$X$1004),0) -> 0
A16: RUN FAMILY | B16: Plays | C16: % of charted | D16: Avg yds
A17: Outside Zone 18-19 | B17: =COUNTIF(Chart!$P$5:$P$1004,A17) -> 0 | C17: =IFERROR(B17/$B$2,0) -> 0 | D17: =IFERROR(AVERAGEIF(Chart!$P$5:$P$1004,A17,Chart!$X$5:$X$1004),0) -> 0
A18: Outside Zone 38-39 (gun) | B18: =COUNTIF(Chart!$P$5:$P$1004,A18) -> 1 | C18: =IFERROR(B18/$B$2,0) -> 1 | D18: =IFERROR(AVERAGEIF(Chart!$P$5:$P$1004,A18,Chart!$X$5:$X$1004),0) -> 6
A19: Inside Zone 15-14 | B19: =COUNTIF(Chart!$P$5:$P$1004,A19) -> 0 | C19: =IFERROR(B19/$B$2,0) -> 0 | D19: =IFERROR(AVERAGEIF(Chart!$P$5:$P$1004,A19,Chart!$X$5:$X$1004),0) -> 0
A20: Inside Zone 35-34 (gun) | B20: =COUNTIF(Chart!$P$5:$P$1004,A20) -> 0 | C20: =IFERROR(B20/$B$2,0) -> 0 | D20: =IFERROR(AVERAGEIF(Chart!$P$5:$P$1004,A20,Chart!$X$5:$X$1004),0) -> 0
A21: Gap 12-13 | B21: =COUNTIF(Chart!$P$5:$P$1004,A21) -> 0 | C21: =IFERROR(B21/$B$2,0) -> 0 | D21: =IFERROR(AVERAGEIF(Chart!$P$5:$P$1004,A21,Chart!$X$5:$X$1004),0) -> 0
A22: Gap 32-33 (gun) | B22: =COUNTIF(Chart!$P$5:$P$1004,A22) -> 0 | C22: =IFERROR(B22/$B$2,0) -> 0 | D22: =IFERROR(AVERAGEIF(Chart!$P$5:$P$1004,A22,Chart!$X$5:$X$1004),0) -> 0
A23: Toss | B23: =COUNTIF(Chart!$P$5:$P$1004,A23) -> 0 | C23: =IFERROR(B23/$B$2,0) -> 0 | D23: =IFERROR(AVERAGEIF(Chart!$P$5:$P$1004,A23,Chart!$X$5:$X$1004),0) -> 0
A24: Draw | B24: =COUNTIF(Chart!$P$5:$P$1004,A24) -> 0 | C24: =IFERROR(B24/$B$2,0) -> 0 | D24: =IFERROR(AVERAGEIF(Chart!$P$5:$P$1004,A24,Chart!$X$5:$X$1004),0) -> 0
A25: Goal Line | B25: =COUNTIF(Chart!$P$5:$P$1004,A25) -> 0 | C25: =IFERROR(B25/$B$2,0) -> 0 | D25: =IFERROR(AVERAGEIF(Chart!$P$5:$P$1004,A25,Chart!$X$5:$X$1004),0) -> 0
A26: QB Designed | B26: =COUNTIF(Chart!$P$5:$P$1004,A26) -> 0 | C26: =IFERROR(B26/$B$2,0) -> 0 | D26: =IFERROR(AVERAGEIF(Chart!$P$5:$P$1004,A26,Chart!$X$5:$X$1004),0) -> 0
A27: Unknown | B27: =COUNTIF(Chart!$P$5:$P$1004,A27) -> 0 | C27: =IFERROR(B27/$B$2,0) -> 0 | D27: =IFERROR(AVERAGEIF(Chart!$P$5:$P$1004,A27,Chart!$X$5:$X$1004),0) -> 0
A29: PERSONNEL | B29: Plays | C29: % of charted | D29: Avg yds
A30: 21 | B30: =COUNTIF(Chart!$H$5:$H$1004,A30) -> 0 | C30: =IFERROR(B30/$B$2,0) -> 0 | D30: =IFERROR(AVERAGEIF(Chart!$H$5:$H$1004,A30,Chart!$X$5:$X$1004),0) -> 0
A31: 12 | B31: =COUNTIF(Chart!$H$5:$H$1004,A31) -> 0 | C31: =IFERROR(B31/$B$2,0) -> 0 | D31: =IFERROR(AVERAGEIF(Chart!$H$5:$H$1004,A31,Chart!$X$5:$X$1004),0) -> 0
A32: 11 | B32: =COUNTIF(Chart!$H$5:$H$1004,A32) -> 1 | C32: =IFERROR(B32/$B$2,0) -> 1 | D32: =IFERROR(AVERAGEIF(Chart!$H$5:$H$1004,A32,Chart!$X$5:$X$1004),0) -> 6
A33: 20 | B33: =COUNTIF(Chart!$H$5:$H$1004,A33) -> 0 | C33: =IFERROR(B33/$B$2,0) -> 0 | D33: =IFERROR(AVERAGEIF(Chart!$H$5:$H$1004,A33,Chart!$X$5:$X$1004),0) -> 0
A34: 10 | B34: =COUNTIF(Chart!$H$5:$H$1004,A34) -> 0 | C34: =IFERROR(B34/$B$2,0) -> 0 | D34: =IFERROR(AVERAGEIF(Chart!$H$5:$H$1004,A34,Chart!$X$5:$X$1004),0) -> 0
A35: 02 | B35: =COUNTIF(Chart!$H$5:$H$1004,A35) -> 0 | C35: =IFERROR(B35/$B$2,0) -> 0 | D35: =IFERROR(AVERAGEIF(Chart!$H$5:$H$1004,A35,Chart!$X$5:$X$1004),0) -> 0
A36: 01 | B36: =COUNTIF(Chart!$H$5:$H$1004,A36) -> 0 | C36: =IFERROR(B36/$B$2,0) -> 0 | D36: =IFERROR(AVERAGEIF(Chart!$H$5:$H$1004,A36,Chart!$X$5:$X$1004),0) -> 0
A37: 22 | B37: =COUNTIF(Chart!$H$5:$H$1004,A37) -> 0 | C37: =IFERROR(B37/$B$2,0) -> 0 | D37: =IFERROR(AVERAGEIF(Chart!$H$5:$H$1004,A37,Chart!$X$5:$X$1004),0) -> 0
A38: 22X | B38: =COUNTIF(Chart!$H$5:$H$1004,A38) -> 0 | C38: =IFERROR(B38/$B$2,0) -> 0 | D38: =IFERROR(AVERAGEIF(Chart!$H$5:$H$1004,A38,Chart!$X$5:$X$1004),0) -> 0
A39: 22Z | B39: =COUNTIF(Chart!$H$5:$H$1004,A39) -> 0 | C39: =IFERROR(B39/$B$2,0) -> 0 | D39: =IFERROR(AVERAGEIF(Chart!$H$5:$H$1004,A39,Chart!$X$5:$X$1004),0) -> 0
A40: 13 | B40: =COUNTIF(Chart!$H$5:$H$1004,A40) -> 0 | C40: =IFERROR(B40/$B$2,0) -> 0 | D40: =IFERROR(AVERAGEIF(Chart!$H$5:$H$1004,A40,Chart!$X$5:$X$1004),0) -> 0
A41: 13X | B41: =COUNTIF(Chart!$H$5:$H$1004,A41) -> 0 | C41: =IFERROR(B41/$B$2,0) -> 0 | D41: =IFERROR(AVERAGEIF(Chart!$H$5:$H$1004,A41,Chart!$X$5:$X$1004),0) -> 0
... A43: 23 | B43: =COUNTIF(Chart!$H$5:$H$1004,A43) -> 0 | C43: =IFERROR(B43/$B$2,0) -> 0 | D43: =IFERROR(AVERAGEIF(Chart!$H$5:$H$1004,A43,Chart!$X$5:$X$1004),0) -> 0
A45: BACKLOG
...
